Traceback (most recent call last):
  File "C:\python_venv\psqlpy_venv\Lib\site-packages\jupyter_cache\executors\utils.py", line 58, in single_nb_execution
    executenb(
  File "C:\python_venv\psqlpy_venv\Lib\site-packages\nbclient\client.py", line 1305, in execute
    return NotebookClient(nb=nb, resources=resources, km=km, **kwargs).execute()
           ^^^^^^^^^^^^^^^^^^^^^^^^^^^^^^^^^^^^^^^^^^^^^^^^^^^^^^^^^^^^^^^^^^^^^
  File "C:\python_venv\psqlpy_venv\Lib\site-packages\jupyter_core\utils\__init__.py", line 173, in wrapped
    return loop.run_until_complete(inner)
           ^^^^^^^^^^^^^^^^^^^^^^^^^^^^^^
  File "C:\Program Files\WindowsApps\PythonSoftwareFoundation.Python.3.11_3.11.1776.0_x64__qbz5n2kfra8p0\Lib\asyncio\base_events.py", line 653, in run_until_complete
    return future.result()
           ^^^^^^^^^^^^^^^
  File "C:\python_venv\psqlpy_venv\Lib\site-packages\nbclient\client.py", line 705, in async_execute
    await self.async_execute_cell(
  File "C:\python_venv\psqlpy_venv\Lib\site-packages\nbclient\client.py", line 1058, in async_execute_cell
    await self._check_raise_for_error(cell, cell_index, exec_reply)
  File "C:\python_venv\psqlpy_venv\Lib\site-packages\nbclient\client.py", line 914, in _check_raise_for_error
    raise CellExecutionError.from_cell_and_msg(cell, exec_reply_content)
nbclient.exceptions.CellExecutionError: An error occurred while executing the following cell:
------------------
fig.add_trace(go.Scattergeo(lon = Sub_data['longitud'], 
                            lat = Sub_data['latitud'], 
                            text = Sub_data['texto'],
                            mode = 'markers',
                            marker=dict(color=Sub_data['color'], size=3)))

fig.update_layout(
    title = 'Distribuci√≥n geogr√°fica de las aves',
    geo_scope='world',
    geo=dict(showcoastlines=True,showocean=True, showframe=False, coastlinecolor="black",
             showcountries=True,showland = True, countrywidth = 0.7,
             landcolor = '#E3DCC3',lakecolor = '#4EA3E1',
             oceancolor ="lightblue" ,projection_type="orthographic",
             lonaxis = dict(showgrid = True,gridcolor = 'white',gridwidth = 0.3),
             lataxis = dict(showgrid = True,gridcolor = 'white',gridwidth = 0.3)),
    title_x=0.5)
fig.show()
------------------


[1;31m---------------------------------------------------------------------------[0m
[1;31mAttributeError[0m                            Traceback (most recent call last)
Cell [1;32mIn[54], line 1[0m
[1;32m----> 1[0m [43mfig[49m[38;5;241;43m.[39;49m[43madd_trace[49m(go[38;5;241m.[39mScattergeo(lon [38;5;241m=[39m Sub_data[[38;5;124m'[39m[38;5;124mlongitud[39m[38;5;124m'[39m], 
[0;32m      2[0m                             lat [38;5;241m=[39m Sub_data[[38;5;124m'[39m[38;5;124mlatitud[39m[38;5;124m'[39m], 
[0;32m      3[0m                             text [38;5;241m=[39m Sub_data[[38;5;124m'[39m[38;5;124mtexto[39m[38;5;124m'[39m],
[0;32m      4[0m                             mode [38;5;241m=[39m [38;5;124m'[39m[38;5;124mmarkers[39m[38;5;124m'[39m,
[0;32m      5[0m                             marker[38;5;241m=[39m[38;5;28mdict[39m(color[38;5;241m=[39mSub_data[[38;5;124m'[39m[38;5;124mcolor[39m[38;5;124m'[39m], size[38;5;241m=[39m[38;5;241m3[39m)))
[0;32m      7[0m fig[38;5;241m.[39mupdate_layout(
[0;32m      8[0m     title [38;5;241m=[39m [38;5;124m'[39m[38;5;124mDistribuci√≥n geogr√°fica de las aves[39m[38;5;124m'[39m,
[0;32m      9[0m     geo_scope[38;5;241m=[39m[38;5;124m'[39m[38;5;124mworld[39m[38;5;124m'[39m,
[1;32m   (...)[0m
[0;32m     15[0m              lataxis [38;5;241m=[39m [38;5;28mdict[39m(showgrid [38;5;241m=[39m [38;5;28;01mTrue[39;00m,gridcolor [38;5;241m=[39m [38;5;124m'[39m[38;5;124mwhite[39m[38;5;124m'[39m,gridwidth [38;5;241m=[39m [38;5;241m0.3[39m)),
[0;32m     16[0m     title_x[38;5;241m=[39m[38;5;241m0.5[39m)
[0;32m     17[0m fig[38;5;241m.[39mshow()

[1;31mAttributeError[0m: 'Figure' object has no attribute 'add_trace'

